<?xml version="1.0" encoding="utf-8"?>
<!-- Editor: Pham The Thinh-->
<!-- =================================================================================== -->
<!-- |    This document was autogenerated by xacro from ur10e.xacro                    | -->
<!-- |    EDITING THIS FILE BY HAND IS NOT RECOMMENDED                                 | -->
<!-- =================================================================================== -->
<robot name="ur10e_rg2">
  <joint name="tool0-rg2" type="fixed">
    <parent link="tool0"/>
    <child link="onrobot_rg2_base_link"/>
    <origin rpy="0. 0. 0" xyz="0. 0. 0."/>
  </joint>
  <link name="onrobot_rg2_base_link">
    <inertial>
      <origin rpy="0 0 0" xyz="0.0 0.0 0.0"/>
      <mass value="0.7"/>
      <inertia ixx="1.0E-03" ixy="1.0E-06" ixz="1.0E-06" iyy="1.0E-03" iyz="1.0E-06" izz="1.0E-03"/>
    </inertial>
    <visual>
      <origin rpy="0 0 0" xyz="0 0 0"/>
      <geometry>
        <mesh filename="meshes/rg2/visual/base_link.stl"/>
      </geometry>
      <material name="">
        <color rgba="0.8 0.8 0.8 1"/>
      </material>
    </visual>
    <collision>
      <origin rpy="0 0 0" xyz="0 0 0"/>
      <geometry>
        <mesh filename="meshes/rg2/collision/base_link.stl"/>
      </geometry>
    </collision>
  </link>
  <gazebo reference="onrobot_rg2_base_link">
    <mu1>1.0</mu1>
    <mu2>1.0</mu2>
    <selfCollide>false</selfCollide>
    <material>Gazebo/White</material>
  </gazebo>
  <link name="left_outer_knuckle">
    <inertial>
      <origin rpy="0 0 0" xyz="0.0 0.0 0.0"/>
      <mass value="0.05"/>
      <inertia ixx="1.0E-03" ixy="1.0E-06" ixz="1.0E-06" iyy="1.0E-03" iyz="1.0E-06" izz="1.0E-03"/>
    </inertial>
    <visual>
      <origin rpy="0 0 0" xyz="0 0 0"/>
      <geometry>
        <mesh filename="meshes/rg2/visual/outer_knuckle.stl"/>
      </geometry>
      <material name="">
        <color rgba="0.8 0.8 0.8 1"/>
      </material>
    </visual>
    <collision>
      <origin rpy="0 0 0" xyz="0 0 0"/>
      <geometry>
        <mesh filename="meshes/rg2/collision/outer_knuckle.stl"/>
      </geometry>
    </collision>
  </link>
  <gazebo reference="left_outer_knuckle">
    <mu1>0.1</mu1>
    <mu2>0.1</mu2>
    <selfCollide>false</selfCollide>
    <material>Gazebo/White</material>
  </gazebo>
  <link name="left_inner_knuckle">
    <inertial>
      <origin rpy="0 0 0" xyz="0.0 0.0 0.0"/>
      <mass value="0.05"/>
      <inertia ixx="1.0E-03" ixy="1.0E-06" ixz="1.0E-06" iyy="1.0E-03" iyz="1.0E-06" izz="1.0E-03"/>
    </inertial>
    <visual>
      <origin rpy="0 0 0" xyz="0 0 0"/>
      <geometry>
        <mesh filename="meshes/rg2/visual/inner_knuckle.stl"/>
      </geometry>
      <material name="">
        <color rgba="0.8 0.8 0.8 1"/>
      </material>
    </visual>
    <collision>
      <origin rpy="0 0 0" xyz="0 0 0"/>
      <geometry>
        <mesh filename="meshes/rg2/collision/inner_knuckle.stl"/>
      </geometry>
    </collision>
  </link>
  <gazebo reference="left_inner_knuckle">
    <mu1>0.1</mu1>
    <mu2>0.1</mu2>
    <selfCollide>false</selfCollide>
    <material>Gazebo/White</material>
  </gazebo>
  <link name="left_inner_finger">
    <inertial>
      <origin rpy="0 0 0" xyz="0.0 0.0 0.0"/>
      <mass value="0.05"/>
      <inertia ixx="1.0E-03" ixy="1.0E-06" ixz="1.0E-06" iyy="1.0E-03" iyz="1.0E-06" izz="1.0E-03"/>
    </inertial>
    <visual>
      <origin rpy="0 0 0" xyz="0 0 0"/>
      <geometry>
        <mesh filename="meshes/rg2/visual/inner_finger.stl"/>
      </geometry>
      <material name="">
        <color rgba="0.1 0.1 0.1 1"/>
      </material>
    </visual>
    <collision>
      <origin rpy="0 0 0" xyz="0 0 0"/>
      <geometry>
        <mesh filename="meshes/rg2/collision/inner_finger.stl"/>
      </geometry>
    </collision>
  </link>
  <gazebo reference="left_inner_finger">
    <kp>1000000.0</kp>
    <kd>1.0</kd>
    <kd>1.0</kd>
    <mu1>1.0</mu1>
    <mu2>1.0</mu2>
    <minDepth>0.00001</minDepth>
    <selfCollide>false</selfCollide>
    <material>Gazebo/Black</material>
  </gazebo>
  <link name="right_outer_knuckle">
    <inertial>
      <origin rpy="0 0 0" xyz="0.0 0.0 0.0"/>
      <mass value="0.05"/>
      <inertia ixx="1.0E-03" ixy="1.0E-06" ixz="1.0E-06" iyy="1.0E-03" iyz="1.0E-06" izz="1.0E-03"/>
    </inertial>
    <visual>
      <origin rpy="0 0 0" xyz="0 0 0"/>
      <geometry>
        <mesh filename="meshes/rg2/visual/outer_knuckle.stl"/>
      </geometry>
      <material name="">
        <color rgba="0.8 0.8 0.8 1"/>
      </material>
    </visual>
    <collision>
      <origin rpy="0 0 0" xyz="0 0 0"/>
      <geometry>
        <mesh filename="meshes/rg2/collision/outer_knuckle.stl"/>
      </geometry>
    </collision>
  </link>
  <gazebo reference="right_outer_knuckle">
    <mu1>0.1</mu1>
    <mu2>0.1</mu2>
    <selfCollide>false</selfCollide>
    <material>Gazebo/White</material>
  </gazebo>
  <link name="right_inner_knuckle">
    <inertial>
      <origin rpy="0 0 0" xyz="0.0 0.0 0.0"/>
      <mass value="0.05"/>
      <inertia ixx="1.0E-03" ixy="1.0E-06" ixz="1.0E-06" iyy="1.0E-03" iyz="1.0E-06" izz="1.0E-03"/>
    </inertial>
    <visual>
      <origin rpy="0 0 0" xyz="0 0 0"/>
      <geometry>
        <mesh filename="meshes/rg2/visual/inner_knuckle.stl"/>
      </geometry>
      <material name="">
        <color rgba="0.8 0.8 0.8 1"/>
      </material>
    </visual>
    <collision>
      <origin rpy="0 0 0" xyz="0 0 0"/>
      <geometry>
        <mesh filename="meshes/rg2/collision/inner_knuckle.stl"/>
      </geometry>
    </collision>
  </link>
  <gazebo reference="right_inner_knuckle">
    <mu1>0.1</mu1>
    <mu2>0.1</mu2>
    <selfCollide>false</selfCollide>
    <material>Gazebo/White</material>
  </gazebo>
  <link name="right_inner_finger">
    <inertial>
      <origin rpy="0 0 0" xyz="0.0 0.0 0.0"/>
      <mass value="0.05"/>
      <inertia ixx="1.0E-03" ixy="1.0E-06" ixz="1.0E-06" iyy="1.0E-03" iyz="1.0E-06" izz="1.0E-03"/>
    </inertial>
    <visual>
      <origin rpy="0 0 0" xyz="0 0 0"/>
      <geometry>
        <mesh filename="meshes/rg2/visual/inner_finger.stl"/>
      </geometry>
      <material name="">
        <color rgba="0.1 0.1 0.1 1"/>
      </material>
    </visual>
    <collision>
      <origin rpy="0 0 0" xyz="0 0 0"/>
      <geometry>
        <mesh filename="meshes/rg2/collision/inner_finger.stl"/>
      </geometry>
    </collision>
  </link>
  <gazebo reference="right_inner_finger">
    <kp>1000000.0</kp>
    <kd>1.0</kd>
    <kd>1.0</kd>
    <mu1>1.0</mu1>
    <mu2>1.0</mu2>
    <minDepth>0.00001</minDepth>
    <selfCollide>false</selfCollide>
    <material>Gazebo/Black</material>
  </gazebo>
  <joint name="finger_joint" type="revolute">
    <origin rpy="0 0 0" xyz="0 -0.017178 0.125797"/>
    <parent link="onrobot_rg2_base_link"/>
    <child link="left_outer_knuckle"/>
    <axis xyz="-1 0 0"/>
    <limit effort="1000" lower="-0.558505" upper="0.785398" velocity="100.0"/>
  </joint>
  <joint name="left_inner_knuckle_joint" type="revolute">
    <origin rpy="0 0 0.0" xyz="0 -0.007678 0.1422970"/>
    <parent link="onrobot_rg2_base_link"/>
    <child link="left_inner_knuckle"/>
    <axis xyz="1 0 0"/>
    <limit effort="1000" lower="-0.785398" upper="0.785398" velocity="100.0"/>
    <mimic joint="finger_joint" multiplier="-1" offset="0"/>
  </joint>
  <joint name="left_inner_finger_joint" type="revolute">
    <origin rpy="0 0 0" xyz="0 -0.039592 0.038177000000000016"/>
    <parent link="left_outer_knuckle"/>
    <child link="left_inner_finger"/>
    <axis xyz="1 0 0"/>
    <limit effort="1000" lower="-0.872665" upper="0.872665" velocity="100.0"/>
    <mimic joint="finger_joint" multiplier="1" offset="0"/>
  </joint>
  <joint name="right_outer_knuckle_joint" type="revolute">
    <origin rpy="0 0 3.141592653589793" xyz="0 0.017178 0.125797"/>
    <parent link="onrobot_rg2_base_link"/>
    <child link="right_outer_knuckle"/>
    <axis xyz="1 0 0"/>
    <limit effort="1000" lower="-0.785398" upper="0.785398" velocity="100.0"/>
    <mimic joint="finger_joint" multiplier="-1" offset="0"/>
  </joint>
  <joint name="right_inner_knuckle_joint" type="revolute">
    <origin rpy="0 0 -3.141592653589793" xyz="0 0.007678 0.1422970"/>
    <parent link="onrobot_rg2_base_link"/>
    <child link="right_inner_knuckle"/>
    <axis xyz="1 0 0"/>
    <limit effort="1000" lower="-0.785398" upper="0.785398" velocity="100.0"/>
    <mimic joint="finger_joint" multiplier="-1" offset="0"/>
  </joint>
  <joint name="right_inner_finger_joint" type="revolute">
    <origin rpy="0 0 0" xyz="0 -0.039592 0.038177000000000016"/>
    <parent link="right_outer_knuckle"/>
    <child link="right_inner_finger"/>
    <axis xyz="1 0 0"/>
    <limit effort="1000" lower="-0.872665" upper="0.872665" velocity="100.0"/>
    <mimic joint="finger_joint" multiplier="1" offset="0"/>
  </joint>
  <transmission name="finger_joint_trans">
    <type>transmission_interface/SimpleTransmission</type>
    <joint name="finger_joint">
      <hardwareInterface>hardware_interface/EffortJointInterface</hardwareInterface>
    </joint>
    <actuator name="finger_joint_motor">
      <hardwareInterface>hardware_interface/EffortJointInterface</hardwareInterface>
      <mechanicalReduction>1</mechanicalReduction>
    </actuator>
  </transmission>
   <disable_collision link1="left_inner_knuckle" link2="left_outer_knuckle"></disable_collision>
  <disable_collision link1="right_inner_knuckle" link2="right_outer_knuckle"></disable_collision>
  <disable_collision link1="left_inner_knuckle" link2="left_inner_finger"></disable_collision>
  <disable_collision link1="right_inner_knuckle" link2="right_inner_finger"></disable_collision>
  <disable_collision link1="left_inner_knuckle" link2="onrobot_rg2_base_link"></disable_collision>
  <disable_collision link1="right_inner_knuckle" link2="onrobot_rg2_base_link"></disable_collision>
  <gazebo>
    <plugin filename="libgazebo_ros_control.so" name="gazebo_ros_control">
      <robotNamespace>/onrobot_rg2</robotNamespace>
      <robotSimType>gazebo_ros_control/DefaultRobotHWSim</robotSimType>
    </plugin>
  </gazebo>
  <gazebo>
    <plugin filename="libroboticsgroup_upatras_gazebo_mimic_joint_plugin.so" name="mimic_left_inner_knuckle_joint">
      <joint>finger_joint</joint>
      <mimicJoint>left_inner_knuckle_joint</mimicJoint>
      <multiplier>-1.0</multiplier>
      <offset>0.0</offset>
      <maxEffort>5.0</maxEffort>
      <!-- <hasPID /> -->
    </plugin>
    <plugin filename="libroboticsgroup_upatras_gazebo_mimic_joint_plugin.so" name="mimic_right_inner_knuckle_joint">
      <joint>finger_joint</joint>
      <mimicJoint>right_inner_knuckle_joint</mimicJoint>
      <multiplier>-1.0</multiplier>
      <offset>0.0</offset>
      <maxEffort>5.0</maxEffort>
      <!-- <hasPID /> -->
    </plugin>
    <plugin filename="libroboticsgroup_upatras_gazebo_mimic_joint_plugin.so" name="mimic_left_inner_finger_joint">
      <joint>finger_joint</joint>
      <mimicJoint>left_inner_finger_joint</mimicJoint>
      <multiplier>1.0</multiplier>
      <offset>0.0</offset>
      <maxEffort>5.0</maxEffort>
      <!-- <hasPID /> -->
    </plugin>
    <plugin filename="libroboticsgroup_upatras_gazebo_mimic_joint_plugin.so" name="mimic_right_inner_finger_joint">
      <joint>finger_joint</joint>
      <mimicJoint>right_inner_finger_joint</mimicJoint>
      <multiplier>1.0</multiplier>
      <offset>0.0</offset>
      <maxEffort>5.0</maxEffort>
      <!-- <hasPID /> -->
    </plugin>
    <plugin filename="libroboticsgroup_upatras_gazebo_mimic_joint_plugin.so" name="mimic_right_outer_knuckle_joint">
      <joint>finger_joint</joint>
      <mimicJoint>right_outer_knuckle_joint</mimicJoint>
      <multiplier>-1.0</multiplier>
      <offset>0.0</offset>
      <maxEffort>5.0</maxEffort>
      <!-- <hasPID /> -->
    </plugin>
  </gazebo>
<!--Load ur10e robot-->
  <link name="world"/>
  <link name="base_link" />
  <link name="base" />
  <link name="base_link_inertia">
    <inertial>
      <origin rpy="0 0 0" xyz="0 0 0" />
      <mass value="4" />
      <inertia ixx="0.00610633101314306" ixy="0" ixz="0" iyy="0.00610633101314306" iyz="0" izz="0.0112500004470348" />
    </inertial>
    <visual>
      <origin rpy="0 0 -3.141593" />
      <geometry>
        <mesh filename="package://meshes/base.dae" scale="1 1 1" />
      </geometry>
    </visual>
    <collision>
      <origin rpy="0 0 -3.141593" />
      <geometry>
        <mesh filename="package://meshes/base.stl" scale="1 1 1" />
      </geometry>
    </collision>
  </link>
  <link name="shoulder_link">
    <inertial>
      <origin rpy="0 0 0" xyz="0 0 0" />
      <mass value="7.7779998779" />
      <inertia ixx="0.0314743109047413" ixy="0" ixz="0" iyy="0.0314743109047413" iyz="0" izz="0.0218756254762411" />
    </inertial>
    <visual>
      <origin rpy="0 0 -3.141593" />
      <geometry>
        <mesh filename="package://meshes/shoulder.dae" scale="1 1 1" />
      </geometry>
    </visual>
    <collision>
      <origin rpy="0 0 -3.141593" />
      <geometry>
        <mesh filename="package://meshes/shoulder.stl" scale="1 1 1" />
      </geometry>
    </collision>
  </link>
  <link name="upper_arm_link">
    <inertial>
      <origin rpy="90 0 0" xyz="-0.306 0 0.175" />
      <mass value="12.9300003052" />
      <inertia ixx="0.036365631967783" ixy="0" ixz="5.17803222521707E-08" iyy="0.421753793954849" iyz="0" izz="0.421753913164139" />
    </inertial>
    <visual>
      <origin rpy="-4.712389 0 -1.570796" xyz="0 0 0.1762" />
      <geometry>
        <mesh filename="package://meshes/upperarm.dae" scale="1 1 1" />
      </geometry>
    </visual>
    <collision>
      <origin rpy="-4.712389 0 -1.570796" xyz="0 0 0.1762" />
      <geometry>
        <mesh filename="package://meshes/upperarm.stl" scale="1 1 1" />
      </geometry>
    </collision>
  </link>
  <link name="forearm_link">
    <inertial>
      <origin rpy="90 0 0" xyz="-0.285775 0 0.0393" />
      <mass value="3.8699998856" />
      <inertia ixx="0.0108843771740794" ixy="0" ixz="1.34236133320087E-08" iyy="0.110793024301529" iyz="0" izz="0.110793054103851" />
    </inertial>
    <visual>
      <origin rpy="-4.712389 0 -1.570796" xyz="0 0 0.0393" />
      <geometry>
        <mesh filename="package://meshes/forearm.dae" scale="1 1 1" />
      </geometry>
    </visual>
    <collision>
      <origin rpy="-4.712389 0 -1.570796" xyz="0 0 0.0393" />
      <geometry>
        <mesh filename="package://meshes/forearm.stl" scale="1 1 1" />
      </geometry>
    </collision>
  </link>
  <link name="wrist_1_link">
    <inertial>
      <origin rpy="0 0 0" xyz="0 0 0" />
      <mass value="1.9600000381" />
      <inertia ixx="0.00510824797675014" ixy="0" ixz="0" iyy="0.00510824797675014" iyz="0" izz="0.00551250018179417" />
    </inertial>
    <visual>
      <origin rpy="-4.712389 0 0" xyz="0 0 -0.135" />
      <geometry>
        <mesh filename="package://meshes/wrist1.dae" scale="1 1 1" />
      </geometry>
    </visual>
    <collision>
      <origin rpy="-4.712389 0 0" xyz="0 0 -0.135" />
      <geometry>
        <mesh filename="package://meshes/wrist1.stl" scale="1 1 1" />
      </geometry>
    </collision>
  </link>
  <link name="wrist_2_link">
    <inertial>
      <origin rpy="0 0 0" xyz="0 0 0" />
      <mass value="1.9600000381" />
      <inertia ixx="0.00510824797675014" ixy="0" ixz="0" iyy="0.00510824797675014" iyz="0" izz="0.00551250018179417" />
    </inertial>
    <visual>
      <origin xyz="0 0 -0.12" />
      <geometry>
        <mesh filename="package://meshes/wrist2.dae" scale="1 1 1" />
      </geometry>
    </visual>
    <collision>
      <origin xyz="0 0 -0.12" />
      <geometry>
        <mesh filename="package://meshes/wrist2.stl" scale="1 1 1" />
      </geometry>
    </collision>
  </link>
  <link name="wrist_3_link">
    <inertial>
      <origin rpy="0 0 0" xyz="0 0 -0.025" />
      <mass value="0.202000007" />
      <inertia ixx="0.000144345773151144" ixy="0" ixz="0" iyy="0.000144345773151144" iyz="0" izz="0.000204525000299327" />
    </inertial>
    <visual>
      <origin rpy="-4.712389 0 0" xyz="0 0 -0.1168" />
      <geometry>
        <mesh filename="package://meshes/wrist3.dae" scale="1 1 1" />
      </geometry>
    </visual>
    <collision>
      <origin rpy="-4.712389 0 0" xyz="0 0 -0.1168" />
      <geometry>
        <mesh filename="package://meshes/wrist3.stl" scale="1 1 1" />
      </geometry>
    </collision>
  </link>
  <link name="flange" />
  <link name="tool0" />
  <!-- Joint chain-->
  <!-- ROS base_link to UR 'Base' Coordinates transform -->
  <joint name="base_link-base_fixed_joint" type="fixed">
    <!-- NOTE: this rotation is only needed as long as base_link itself is
                 not corrected wrt the real robot (ie: rotated over 180
                 degrees)
      -->
    <origin rpy="0 0 -3.14159265359" xyz="0 0 0"/>
    <parent link="base_link"/>
    <child link="base"/>
  </joint>
  <joint name="base_link-base_link_inertia" type="fixed">
    <origin rpy="0 0 -3.141593" />
    <parent link="base_link" />
    <child link="base_link_inertia" />
  </joint>
  <joint name="shoulder_pan_joint" type="revolute">
    <origin xyz="0 0 0.1807" />
    <parent link="base_link_inertia" />
    <child link="shoulder_link" />
    <axis xyz="0 0 1" />
    <limit lower="-6.28318525850773" upper="6.28318525850773" effort="330" velocity="7" />
  </joint>
  <joint name="shoulder_lift_joint" type="revolute">
    <origin rpy="-4.712389 0 0" />
    <parent link="shoulder_link" />
    <child link="upper_arm_link" />
    <axis xyz="0 0 1" />
    <limit lower="-6.28318525850773" upper="6.28318525850773" effort="330" velocity="7" />
  </joint>
  <joint name="elbow_joint" type="revolute">
    <origin xyz="-0.6127 0 0" />
    <parent link="upper_arm_link" />
    <child link="forearm_link" />
    <axis xyz="0 0 1" />
    <limit lower="-3.14159262925386" upper="3.14159262925386" effort="150" velocity="7" />
  </joint>
  <joint name="wrist_1_joint" type="revolute">
    <origin xyz="-0.57155 0 0.17415" />
    <parent link="forearm_link" />
    <child link="wrist_1_link" />
    <axis xyz="0 0 1" />
    <limit lower="-6.28318525850773" upper="6.28318525850773" effort="56" velocity="7" />
  </joint>
  <joint name="wrist_2_joint" type="revolute">
    <origin rpy="-4.712389 0 0" xyz="0 -0.11985 0" />
    <parent link="wrist_1_link" />
    <child link="wrist_2_link" />
    <axis xyz="0 0 1" />
    <limit lower="-6.28318525850773" upper="6.28318525850773" effort="56" velocity="7" />
  </joint>
  <joint name="wrist_3_joint" type="revolute">
    <origin rpy="-1.570796 0 0" xyz="0 0.11655 0" />
    <parent link="wrist_2_link" />
    <child link="wrist_3_link" />
    <axis xyz="0 0 1" />
    <limit lower="-6.28318525850773" upper="6.28318525850773" effort="56" velocity="7" />
  </joint>
  <joint name="wrist_3-flange" type="fixed">
    <origin rpy="0 4.712389 -1.570796" />
    <parent link="wrist_3_link" />
    <child link="flange" />
  </joint>
  <!-- Frame coincident with all-zeros TCP on UR controller -->
  <joint name="flange-tool0" type="fixed">
    <origin rpy="-4.712389 0 -4.712389" />
    <parent link="flange" />
    <child link="tool0" />
  </joint>
  <!-- define the ur10e's position and orientation in the world coordinate system -->
  
  <joint name="world_joint" type="fixed">
    <parent link="world"/>
    <child link="base_link"/>
    <!-- TODO: check base_link name of robot -->
    <origin rpy="0.0 0.0 0.0" xyz="0.0 0.0 0.77"/>
  </joint>
  <!-- Transmission on Robot-->
  <transmission name="shoulder_pan_trans">
  <type>transmission_interface/SimpleTransmission</type>
  <joint name="shoulder_pan_joint">
    <hardwareInterface>hardware_interface/PositionJointInterface</hardwareInterface>
  </joint>
  <actuator name="shoulder_pan_motor">
    <mechanicalReduction>1</mechanicalReduction>
  </actuator>
</transmission>
<transmission name="shoulder_lift_trans">
  <type>transmission_interface/SimpleTransmission</type>
  <joint name="shoulder_lift_joint">
    <hardwareInterface>hardware_interface/PositionJointInterface</hardwareInterface>
  </joint>
  <actuator name="shoulder_lift_motor">
    <mechanicalReduction>1</mechanicalReduction>
  </actuator>
</transmission>
<transmission name="elbow_trans">
  <type>transmission_interface/SimpleTransmission</type>
  <joint name="elbow_joint">
    <hardwareInterface>hardware_interface/PositionJointInterface</hardwareInterface>
  </joint>
  <actuator name="elbow_motor">
    <mechanicalReduction>1</mechanicalReduction>
  </actuator>
</transmission>
<transmission name="wrist_1_trans">
  <type>transmission_interface/SimpleTransmission</type>
  <joint name="wrist_1_joint">
    <hardwareInterface>hardware_interface/PositionJointInterface</hardwareInterface>
  </joint>
  <actuator name="wrist_1_motor">
    <mechanicalReduction>1</mechanicalReduction>
  </actuator>
</transmission>
<transmission name="wrist_2_trans">
  <type>transmission_interface/SimpleTransmission</type>
  <joint name="wrist_2_joint">
    <hardwareInterface>hardware_interface/PositionJointInterface</hardwareInterface>
  </joint>
  <actuator name="wrist_2_motor">
    <mechanicalReduction>1</mechanicalReduction>
  </actuator>
</transmission>
<transmission name="wrist_3_trans">
  <type>transmission_interface/SimpleTransmission</type>
  <joint name="wrist_3_joint">
    <hardwareInterface>hardware_interface/PositionJointInterface</hardwareInterface>
  </joint>
  <actuator name="wrist_3_motor">
    <mechanicalReduction>1</mechanicalReduction>
  </actuator>
</transmission>
<transmission name="finger_joint_trans">
    <type>transmission_interface/SimpleTransmission</type>
    <joint name="finger_joint">
      <hardwareInterface>hardware_interface/EffortJointInterface</hardwareInterface>
    </joint>
    <actuator name="finger_joint_motor">
      <hardwareInterface>hardware_interface/EffortJointInterface</hardwareInterface>
      <mechanicalReduction>1</mechanicalReduction>
    </actuator>
  </transmission>
</robot>
