<?xml version="1.0" encoding="utf-8"?>
<!-- Editor: Pham The Thinh-->
<!-- =================================================================================== -->
<!-- |    This document was autogenerated by xacro from ur10e.xacro                    | -->
<!-- |    EDITING THIS FILE BY HAND IS NOT RECOMMENDED                                 | -->
<!-- =================================================================================== -->
<robot name="ur10e_rg2">
<!--Load ur10e robot-->
  <link name="world"/>
  <link name="base_link" />
  <link name="base" />
  <link name="base_link_inertia">
    <inertial>
      <origin rpy="0 0 0" xyz="0 0 0" />
      <mass value="4" />
      <inertia ixx="0.00610633101314306" ixy="0" ixz="0" iyy="0.00610633101314306" iyz="0" izz="0.0112500004470348" />
    </inertial>
    <visual>
      <origin rpy="0 0 -3.141593" />
      <geometry>
        <mesh filename="package://meshes/base.dae" scale="1 1 1" />
      </geometry>
    </visual>
    <collision>
      <origin rpy="0 0 -3.141593" />
      <geometry>
        <mesh filename="package://meshes/base.stl" scale="1 1 1" />
      </geometry>
    </collision>
  </link>
  <link name="shoulder_link">
    <inertial>
      <origin rpy="0 0 0" xyz="0 0 0" />
      <mass value="7.7779998779" />
      <inertia ixx="0.0314743109047413" ixy="0" ixz="0" iyy="0.0314743109047413" iyz="0" izz="0.0218756254762411" />
    </inertial>
    <visual>
      <origin rpy="0 0 -3.141593" />
      <geometry>
        <mesh filename="package://meshes/shoulder.dae" scale="1 1 1" />
      </geometry>
    </visual>
    <collision>
      <origin rpy="0 0 -3.141593" />
      <geometry>
        <mesh filename="package://meshes/shoulder.stl" scale="1 1 1" />
      </geometry>
    </collision>
  </link>
  <link name="upper_arm_link">
    <inertial>
      <origin rpy="90 0 0" xyz="-0.306 0 0.175" />
      <mass value="12.9300003052" />
      <inertia ixx="0.036365631967783" ixy="0" ixz="5.17803222521707E-08" iyy="0.421753793954849" iyz="0" izz="0.421753913164139" />
    </inertial>
    <visual>
      <origin rpy="-4.712389 0 -1.570796" xyz="0 0 0.1762" />
      <geometry>
        <mesh filename="package://meshes/upperarm.dae" scale="1 1 1" />
      </geometry>
    </visual>
    <collision>
      <origin rpy="-4.712389 0 -1.570796" xyz="0 0 0.1762" />
      <geometry>
        <mesh filename="package://meshes/upperarm.stl" scale="1 1 1" />
      </geometry>
    </collision>
  </link>
  <link name="forearm_link">
    <inertial>
      <origin rpy="90 0 0" xyz="-0.285775 0 0.0393" />
      <mass value="3.8699998856" />
      <inertia ixx="0.0108843771740794" ixy="0" ixz="1.34236133320087E-08" iyy="0.110793024301529" iyz="0" izz="0.110793054103851" />
    </inertial>
    <visual>
      <origin rpy="-4.712389 0 -1.570796" xyz="0 0 0.0393" />
      <geometry>
        <mesh filename="package://meshes/forearm.dae" scale="1 1 1" />
      </geometry>
    </visual>
    <collision>
      <origin rpy="-4.712389 0 -1.570796" xyz="0 0 0.0393" />
      <geometry>
        <mesh filename="package://meshes/forearm.stl" scale="1 1 1" />
      </geometry>
    </collision>
  </link>
  <link name="wrist_1_link">
    <inertial>
      <origin rpy="0 0 0" xyz="0 0 0" />
      <mass value="1.9600000381" />
      <inertia ixx="0.00510824797675014" ixy="0" ixz="0" iyy="0.00510824797675014" iyz="0" izz="0.00551250018179417" />
    </inertial>
    <visual>
      <origin rpy="-4.712389 0 0" xyz="0 0 -0.135" />
      <geometry>
        <mesh filename="package://meshes/wrist1.dae" scale="1 1 1" />
      </geometry>
    </visual>
    <collision>
      <origin rpy="-4.712389 0 0" xyz="0 0 -0.135" />
      <geometry>
        <mesh filename="package://meshes/wrist1.stl" scale="1 1 1" />
      </geometry>
    </collision>
  </link>
  <link name="wrist_2_link">
    <inertial>
      <origin rpy="0 0 0" xyz="0 0 0" />
      <mass value="1.9600000381" />
      <inertia ixx="0.00510824797675014" ixy="0" ixz="0" iyy="0.00510824797675014" iyz="0" izz="0.00551250018179417" />
    </inertial>
    <visual>
      <origin xyz="0 0 -0.12" />
      <geometry>
        <mesh filename="package://meshes/wrist2.dae" scale="1 1 1" />
      </geometry>
    </visual>
    <collision>
      <origin xyz="0 0 -0.12" />
      <geometry>
        <mesh filename="package://meshes/wrist2.stl" scale="1 1 1" />
      </geometry>
    </collision>
  </link>
  <link name="wrist_3_link">
    <inertial>
      <origin rpy="0 0 0" xyz="0 0 -0.025" />
      <mass value="0.202000007" />
      <inertia ixx="0.000144345773151144" ixy="0" ixz="0" iyy="0.000144345773151144" iyz="0" izz="0.000204525000299327" />
    </inertial>
    <visual>
      <origin rpy="-4.712389 0 0" xyz="0 0 -0.1168" />
      <geometry>
        <mesh filename="package://meshes/wrist3.dae" scale="1 1 1" />
      </geometry>
    </visual>
    <collision>
      <origin rpy="-4.712389 0 0" xyz="0 0 -0.1168" />
      <geometry>
        <mesh filename="package://meshes/wrist3.stl" scale="1 1 1" />
      </geometry>
    </collision>
  </link>
  <link name="flange" />
  <link name="tool0" />
  <!-- Joint chain-->
  <!-- ROS base_link to UR 'Base' Coordinates transform -->
  <joint name="base_link-base_fixed_joint" type="fixed">
    <!-- NOTE: this rotation is only needed as long as base_link itself is
                 not corrected wrt the real robot (ie: rotated over 180
                 degrees)
      -->
    <origin rpy="0 0 -3.14159265359" xyz="0 0 0"/>
    <parent link="base_link"/>
    <child link="base"/>
  </joint>
  <joint name="base_link-base_link_inertia" type="fixed">
    <origin rpy="0 0 -3.141593" />
    <parent link="base_link" />
    <child link="base_link_inertia" />
  </joint>
  <joint name="shoulder_pan_joint" type="revolute">
    <origin xyz="0 0 0.1807" />
    <parent link="base_link_inertia" />
    <child link="shoulder_link" />
    <axis xyz="0 0 1" />
    <limit lower="-6.28318525850773" upper="6.28318525850773" effort="330" velocity="7" />
  </joint>
  <joint name="shoulder_lift_joint" type="revolute">
    <origin rpy="-4.712389 0 0" />
    <parent link="shoulder_link" />
    <child link="upper_arm_link" />
    <axis xyz="0 0 1" />
    <limit lower="-6.28318525850773" upper="6.28318525850773" effort="330" velocity="7" />
  </joint>
  <joint name="elbow_joint" type="revolute">
    <origin xyz="-0.6127 0 0" />
    <parent link="upper_arm_link" />
    <child link="forearm_link" />
    <axis xyz="0 0 1" />
    <limit lower="-3.14159262925386" upper="3.14159262925386" effort="150" velocity="7" />
  </joint>
  <joint name="wrist_1_joint" type="revolute">
    <origin xyz="-0.57155 0 0.17415" />
    <parent link="forearm_link" />
    <child link="wrist_1_link" />
    <axis xyz="0 0 1" />
    <limit lower="-6.28318525850773" upper="6.28318525850773" effort="56" velocity="7" />
  </joint>
  <joint name="wrist_2_joint" type="revolute">
    <origin rpy="-4.712389 0 0" xyz="0 -0.11985 0" />
    <parent link="wrist_1_link" />
    <child link="wrist_2_link" />
    <axis xyz="0 0 1" />
    <limit lower="-6.28318525850773" upper="6.28318525850773" effort="56" velocity="7" />
  </joint>
  <joint name="wrist_3_joint" type="revolute">
    <origin rpy="-1.570796 0 0" xyz="0 0.11655 0" />
    <parent link="wrist_2_link" />
    <child link="wrist_3_link" />
    <axis xyz="0 0 1" />
    <limit lower="-6.28318525850773" upper="6.28318525850773" effort="56" velocity="7" />
  </joint>
  <joint name="wrist_3-flange" type="fixed">
    <origin rpy="0 4.712389 -1.570796" />
    <parent link="wrist_3_link" />
    <child link="flange" />
  </joint>
  <!-- Frame coincident with all-zeros TCP on UR controller -->
  <joint name="flange-tool0" type="fixed">
    <origin rpy="-4.712389 0 -4.712389" />
    <parent link="flange" />
    <child link="tool0" />
  </joint>
  <!-- define the ur10e's position and orientation in the world coordinate system -->
  
  <joint name="world_joint" type="fixed">
    <parent link="world"/>
    <child link="base_link"/>
    <!-- TODO: check base_link name of robot -->
    <origin rpy="0.0 0.0 0.0" xyz="0.0 0.0 0.77"/>
  </joint>
  <!-- Transmission on Robot-->
  <transmission name="shoulder_pan_trans">
  <type>transmission_interface/SimpleTransmission</type>
  <joint name="shoulder_pan_joint">
    <hardwareInterface>hardware_interface/PositionJointInterface</hardwareInterface>
  </joint>
  <actuator name="shoulder_pan_motor">
    <mechanicalReduction>1</mechanicalReduction>
  </actuator>
</transmission>
<transmission name="shoulder_lift_trans">
  <type>transmission_interface/SimpleTransmission</type>
  <joint name="shoulder_lift_joint">
    <hardwareInterface>hardware_interface/PositionJointInterface</hardwareInterface>
  </joint>
  <actuator name="shoulder_lift_motor">
    <mechanicalReduction>1</mechanicalReduction>
  </actuator>
</transmission>
<transmission name="elbow_trans">
  <type>transmission_interface/SimpleTransmission</type>
  <joint name="elbow_joint">
    <hardwareInterface>hardware_interface/PositionJointInterface</hardwareInterface>
  </joint>
  <actuator name="elbow_motor">
    <mechanicalReduction>1</mechanicalReduction>
  </actuator>
</transmission>
<transmission name="wrist_1_trans">
  <type>transmission_interface/SimpleTransmission</type>
  <joint name="wrist_1_joint">
    <hardwareInterface>hardware_interface/PositionJointInterface</hardwareInterface>
  </joint>
  <actuator name="wrist_1_motor">
    <mechanicalReduction>1</mechanicalReduction>
  </actuator>
</transmission>
<transmission name="wrist_2_trans">
  <type>transmission_interface/SimpleTransmission</type>
  <joint name="wrist_2_joint">
    <hardwareInterface>hardware_interface/PositionJointInterface</hardwareInterface>
  </joint>
  <actuator name="wrist_2_motor">
    <mechanicalReduction>1</mechanicalReduction>
  </actuator>
</transmission>
<transmission name="wrist_3_trans">
  <type>transmission_interface/SimpleTransmission</type>
  <joint name="wrist_3_joint">
    <hardwareInterface>hardware_interface/PositionJointInterface</hardwareInterface>
  </joint>
  <actuator name="wrist_3_motor">
    <mechanicalReduction>1</mechanicalReduction>
  </actuator>
</transmission>
<transmission name="finger_joint_trans">
    <type>transmission_interface/SimpleTransmission</type>
    <joint name="finger_joint">
      <hardwareInterface>hardware_interface/EffortJointInterface</hardwareInterface>
    </joint>
    <actuator name="finger_joint_motor">
      <hardwareInterface>hardware_interface/EffortJointInterface</hardwareInterface>
      <mechanicalReduction>1</mechanicalReduction>
    </actuator>
  </transmission>
</robot>
